<?xml version="1.0"?>
<robot xmlns:xacro="http://www.ros.org/wiki/xacro" >

  <!-- Base -->

    
  <joint name="shoulder_joint" type="revolute">
    <origin rpy="0 1.57079637 0" xyz="${-0.291179+1.8143} ${0.967229-0.004215} ${-0.50857-0.1132-0.560595}"/>
    <parent link="base_link"/>
    <child link="shoulder_link"/>
    <limit effort="100" lower="-3.14" upper="3.14" velocity="100"/>
    <dynamics damping="0.1" friction="0.1"/>
    <axis xyz="0 0 1"/>
  </joint>
  <link name="shoulder_link">
    <visual>
      <geometry>
        <mesh filename="package://rov_ricketts_description/meshes/DAE/shoulder/shoulder.dae"/>
      </geometry>
    </visual>
    <collision>
      <geometry>
        <mesh filename="package://rov_ricketts_description/meshes/STL/shoulder/shoulder.stl"/>
      </geometry>
    </collision>
    <inertial>
      <origin xyz="0.0000223482 0.0000414609 0.0066287000"/>
      <mass value="0.480879"/>
      <inertia ixx="0.222" ixy="0" ixz="0" iyy="0.395" iyz="0" izz="0.222"/>
    </inertial>
    <surface>
      <friction>
        <ode>
          <mu1>1.2</mu1>
          <mu2>1.2</mu2>
          <kp>1e15</kp>
          <kd>1e13</kd>
        </ode>
      </friction>
      <bounce>
        <restitution_coefficient>0.01</restitution_coefficient>
        <threshold>0</threshold>
      </bounce>
      <contact>
        <ode>
          <max_vel>10</max_vel>
        </ode>
      </contact>
    </surface>
  </link>
  <joint name="upper_arm_joint" type="revolute">
    <origin rpy="0 -1.57079637 0" xyz="0.122041  -0.036335   0.195604 "/>
    <parent link="shoulder_link"/>
    <child link="upper_arm_link"/>
    <limit effort="100" lower="-3.14" upper="3.14" velocity="100"/>
    <dynamics damping="0.1" friction="0.1"/>
    <axis xyz="0 1 0"/>
  </joint>
  <link name="upper_arm_link">
    <visual>
      <geometry>
        <mesh filename="package://rov_ricketts_description/meshes/DAE/upper_arm/upper_arm.dae"/>
      </geometry>
    </visual>
    <collision>
      <geometry>
        <mesh filename="package://rov_ricketts_description/meshes/STL/upper_arm/upper_arm.stl"/>
      </geometry>
    </collision>
    <inertial>
      <origin xyz="0.0 0.0 0.0"/>
      <mass value="0.298"/>
      <inertia ixx="0.002176" ixy="-0.0000030658" ixz="0.0" iyy="0.00005757" iyz="0.0" izz="0.002186"/>
    </inertial>
    <surface>
      <friction>
        <ode>
          <mu1>1.2</mu1>
          <mu2>1.2</mu2>
          <kp>1e15</kp>
          <kd>1e13</kd>
        </ode>
      </friction>
      <bounce>
        <restitution_coefficient>0.01</restitution_coefficient>
        <threshold>0</threshold>
      </bounce>
      <contact>
        <ode>
          <max_vel>10</max_vel>
        </ode>
      </contact>
    </surface>
  </link>
  <joint name="elbow_joint" type="revolute">
    <origin rpy="0 0 0" xyz="0.0 0.0 0.0685"/>
    <parent link="upper_arm_link"/>
    <child link="elbow_link"/>
    <limit effort="100" lower="-3.14" upper="3.14" velocity="100"/>
    <dynamics damping="0.1" friction="0.1"/>
    <axis xyz="1 0 0"/>
  </joint>
  <link name="elbow_link">
    <visual>
      <geometry>
        <mesh filename="package://rov_ricketts_description/meshes/DAE/elbow/elbow.dae"/>
      </geometry>
    </visual>
    <collision>
      <geometry>
        <mesh filename="package://rov_ricketts_description/meshes/STL/elbow/elbow.stl"/>
      </geometry>
    </collision>
    <inertial>
      <origin xyz="0.1079630000 0.0001158760 0"/>
      <mass value="0.234589"/>
      <inertia ixx="0.00003971" ixy="0.0000023528" ixz="0.0" iyy="0.0008878" iyz="0.0" izz="0.000888"/>
    </inertial>
    <surface>
      <friction>
        <ode>
          <mu1>1.2</mu1>
          <mu2>1.2</mu2>
          <kp>1e15</kp>
          <kd>1e13</kd>
        </ode>
      </friction>
      <bounce>
        <restitution_coefficient>0.01</restitution_coefficient>
        <threshold>0</threshold>
      </bounce>
      <contact>
        <ode>
          <max_vel>10</max_vel>
        </ode>
      </contact>
    </surface>
  </link>
  <joint name="lower_arm_joint" type="revolute">
    <origin rpy="0 -1.3089969750000001 0" xyz="0.0 0.0 0.078"/>
    <parent link="elbow_link"/>
    <child link="lower_arm_link"/>
    <limit effort="100" lower="-3.14" upper="3.14" velocity="100"/>
    <dynamics damping="0.1" friction="0.1"/>
    <axis xyz="0 1 0"/>
  </joint>
  <link name="lower_arm_link">
    <visual>
      <geometry>
        <mesh filename="package://rov_ricketts_description/meshes/DAE/lower_arm/lower_arm.dae"/>
      </geometry>
    </visual>
    <collision>
      <geometry>
        <mesh filename="package://rov_ricketts_description/meshes/STL/lower_arm/lower_arm.stl"/>
      </geometry>
    </collision>
    <inertial>
      <origin xyz="0.0374395000 0.0052225200 0"/>
      <mass value="0.220991"/>
      <inertia ixx="0.00006369" ixy="-0.00002292" ixz="0.0" iyy="0.0001677" iyz="0.0" izz="0.0001834"/>
    </inertial>
    <surface>
      <friction>
        <ode>
          <mu1>1.2</mu1>
          <mu2>1.2</mu2>
          <kp>1e15</kp>
          <kd>1e13</kd>
        </ode>
      </friction>
      <bounce>
        <restitution_coefficient>0.01</restitution_coefficient>
        <threshold>0</threshold>
      </bounce>
      <contact>
        <ode>
          <max_vel>10</max_vel>
        </ode>
      </contact>
    </surface>
  </link>
  <joint name="wrist_joint" type="revolute">
    <origin rpy="0 -1.832595765 0" xyz="0.0 0.0 0.083"/>
    <parent link="lower_arm_link"/>
    <child link="wrist_link"/>
    <limit effort="100" lower="-3.14" upper="3.14" velocity="100"/>
    <dynamics damping="0.1" friction="0.1"/>
    <axis xyz="0 1 0"/>
  </joint>
  <link name="wrist_link">
    <visual>
      <geometry>
        <mesh filename="package://rov_ricketts_description/meshes/DAE/wrist/wrist.dae"/>
      </geometry>
    </visual>
    <collision>
      <geometry>
        <mesh filename="package://rov_ricketts_description/meshes/STL/wrist/wrist.stl"/>
      </geometry>
    </collision>
    <inertial>
      <origin xyz="0.0 0.0 0.0"/>
      <mass value="0.085"/>
      <inertia ixx="0.00003082" ixy="0.0000000191" ixz="0.0000000023" iyy="0.00002822" iyz="0.0000025481" izz="0.00003152"/>
    </inertial>
    <surface>
      <friction>
        <ode>
          <mu1>1.2</mu1>
          <mu2>1.2</mu2>
          <kp>1e15</kp>
          <kd>1e13</kd>
        </ode>
      </friction>
      <bounce>
        <restitution_coefficient>0.01</restitution_coefficient>
        <threshold>0</threshold>
      </bounce>
      <contact>
        <ode>
          <max_vel>10</max_vel>
        </ode>
      </contact>
    </surface>
  </link>
  <joint name="gripper_joint" type="revolute">
    <origin rpy="0 0 0" xyz="0.0 0.0 0.122"/>
    <parent link="wrist_link"/>
    <child link="gripper_link"/>
    <limit effort="100" lower="-3.14" upper="3.14" velocity="100"/>
    <dynamics damping="0.1" friction="0.1"/>
    <axis xyz="0 0 1"/>
  </joint>
  <link name="gripper_link">
    <visual>
      <geometry>
        <mesh filename="package://rov_ricketts_description/meshes/DAE/gripper/gripper.dae"/>
      </geometry>
    </visual>
    <collision>
      <geometry>
        <mesh filename="package://rov_ricketts_description/meshes/STL/gripper/gripper.stl"/>
      </geometry>
    </collision>
    <inertial>
      <origin xyz="0.0 0.0 0.0"/>
      <mass value="0.25"/>
      <inertia ixx="0.00002537" ixy="0.0" ixz="0.0" iyy="0.00001836" iyz="0.000000434" izz="0.00001674"/>
    </inertial>
    <surface>
      <friction>
        <ode>
          <mu1>1.2</mu1>
          <mu2>1.2</mu2>
          <kp>1e15</kp>
          <kd>1e13</kd>
        </ode>
      </friction>
      <bounce>
        <restitution_coefficient>0.01</restitution_coefficient>
        <threshold>0</threshold>
      </bounce>
      <contact>
        <ode>
          <max_vel>10</max_vel>
        </ode>
      </contact>
    </surface>
  </link>

  <gazebo reference="gripper_link">
          <mu1>1.2</mu1>
          <mu2>1.2</mu2>
          <kp>1e15</kp>
          <kd>1e13</kd>
    <fdir1>1 0 0</fdir1>
    <maxVel>1.0</maxVel>
    <minDepth>0.002</minDepth>
  </gazebo>

  <joint name="finger_joint" type="revolute">
    <origin rpy="-0.52359879 0 0" xyz="0.0 0.01475 -0.037"/>
    <parent link="gripper_link"/>
    <child link="finger_link"/>
    <limit effort="100" lower="-1.57" upper="1.57" velocity="100"/>
    <dynamics damping="0.005" friction="0.039"/>
    <axis xyz="1 0 0"/>
  </joint>
  <link name="finger_link">
    <visual>
      <geometry>
        <mesh filename="package://rov_ricketts_description/meshes/DAE/finger/finger.dae"/>
      </geometry>
    </visual>
    <collision>
      <geometry>
        <mesh filename="package://rov_ricketts_description/meshes/STL/finger/finger.stl"/>
      </geometry>
    </collision>
    <inertial>
      <origin xyz="0.0 0.0 0.0"/>
      <mass value="0.016"/>
      <inertia ixx="0.00009" ixy="0.0" ixz="0.0" iyy="0.00009" iyz="0.0" izz="0.00002"/>
    </inertial>
    <surface>
      <friction>
        <ode>
          <mu1>1.2</mu1>
          <mu2>1.2</mu2>
          <kp>1e15</kp>
          <kd>1e13</kd>
        </ode>
      </friction>
      <bounce>
        <restitution_coefficient>0.01</restitution_coefficient>
        <threshold>0</threshold>
      </bounce>
      <contact>
        <ode>
          <max_vel>10</max_vel>
        </ode>
      </contact>
    </surface>
  </link>

  <gazebo reference="finger_link">
          <mu1>1.2</mu1>
          <mu2>1.2</mu2>
          <kp>1e15</kp>
          <kd>1e13</kd>
    <fdir1>1 0 0</fdir1>
    <maxVel>1.0</maxVel>
    <minDepth>0.002</minDepth>
  </gazebo>


  <!-- STEP 11 - Gripper camera -->
  <joint type="fixed" name="gripper_camera_joint">
    <origin xyz="0.0 0.0 0.0" rpy="0 -1.5707 0"/>
    <child link="gripper_camera_link"/>
    <parent link="gripper_link"/>
  </joint>

  <link name='gripper_camera_link'>
    <pose>0 0 0 0 0 0</pose>
    <inertial>
      <mass value="1.0e-03"/>
      <origin xyz="0 0 0" rpy="0 0 0"/>
      <inertia
          ixx="1e-6" ixy="0" ixz="0"
          iyy="1e-6" iyz="0"
          izz="1e-6"
      />
    </inertial>

    <visual>
      <origin xyz="0 0 0" rpy="0 0 0"/>
      <geometry>
        <box size=".01 .01 .01"/>
      </geometry>
      <material name="red"/>
    </visual>
  </link>

  <joint type="fixed" name="gripper_camera_optical_joint">
    <origin xyz="0 0 0" rpy="-1.5707 0 -1.5707"/>
    <child link="gripper_camera_link_optical"/>
    <parent link="gripper_camera_link"/>
  </joint>

  <link name="gripper_camera_link_optical">
  </link>


  <gazebo>
    <plugin
        filename="gz-sim-joint-state-publisher-system"
        name="gz::sim::systems::JointStatePublisher">
        <topic>joint_states</topic>
        <joint_name>shoulder_joint</joint_name>
        <joint_name>upper_arm_joint</joint_name>
        <joint_name>elbow_joint</joint_name>
        <joint_name>lower_arm_joint</joint_name>
        <joint_name>wrist_joint</joint_name>
        <joint_name>gripper_joint</joint_name>
        <joint_name>finger_joint</joint_name>

    </plugin>
  </gazebo>

  <gazebo reference="gripper_camera_link">
    <sensor name="camera" type="camera">
      <camera>
        <horizontal_fov>1.3962634</horizontal_fov>
        <image>
          <width>640</width>
          <height>480</height>
          <format>R8G8B8</format>
        </image>
        <clip>
          <near>0.1</near>
          <far>15</far>
        </clip>
        <noise>
          <type>gaussian</type>
          <!-- Noise is sampled independently per pixel on each frame.
               That pixel's noise value is added to each of its color
               channels, which at that point lie in the range [0,1]. -->
          <mean>0.0</mean>
          <stddev>0.007</stddev>
        </noise>
        <optical_frame_id>gripper_camera_link_optical</optical_frame_id>
        <camera_info_topic>gripper_camera/camera_info</camera_info_topic>
      </camera>
      <always_on>1</always_on>
      <update_rate>20</update_rate>
      <visualize>true</visualize>
      <topic>gripper_camera/image</topic>
    </sensor>
  </gazebo>
</robot>