<?xml version="1.0" ?>
<!-- =================================================================================== -->
<!-- |    This document was autogenerated by xacro from /home/harivathsha/rov-ricketts/src/ROV-Ricketts-ros2/rov_ricketts_description/urdf/Ricketts.urdf.xacro | -->
<!-- |    EDITING THIS FILE BY HAND IS NOT RECOMMENDED                                 | -->
<!-- =================================================================================== -->
<robot name="Rov_Ricketts">
  <joint name="camera_joint" type="fixed">
    <parent link="base_link"/>
    <child link="camera_link"/>
    <origin rpy="0 0.18 0" xyz="0.276 0 0.181"/>
  </joint>
  <link name="camera_link">
    <visual>
      <origin xyz="-0.36 0.0 -0.04"/>
      <geometry>
        <box size="0.010 0.03 0.03"/>
      </geometry>
      <material name="black"/>
    </visual>
    <visual>
      <origin xyz="-0.36 0.0 -0.08"/>
      <geometry>
        <cylinder length="0.1" radius="0.002"/>
      </geometry>
      <material name="black"/>
    </visual>
  </link>
  <joint name="camera_optical_joint" type="fixed">
    <parent link="camera_link"/>
    <child link="camera_link_optical"/>
    <origin rpy="-1.5707963267948966 0 -1.5707963267948966" xyz="0 0 0"/>
  </joint>
  <link name="camera_link_optical"/>
  <gazebo reference="camera_link">
    <material>Gazebo/Black</material>
    <sensor name="camera" type="camera">
      <pose> 0 0 0 0 0 0 </pose>
      <visualize>true</visualize>
      <update_rate>10</update_rate>
      <camera>
        <camera_info_topic>camera/camera_info</camera_info_topic>
        <horizontal_fov>1.089</horizontal_fov>
        <image>
          <format>R8G8B8</format>
          <width>640</width>
          <height>480</height>
        </image>
        <clip>
          <near>0.05</near>
          <far>8.0</far>
        </clip>
      </camera>
      <topic>camera/image_raw</topic>
    </sensor>
  </gazebo>
  <material name="black">
    <color rgba="0.0 0.0 0.0 1.0"/>
  </material>
  <material name="white">
    <color rgba="1.0 1.0 1.0 1.0"/>
  </material>
  <material name="red">
    <color rgba="0.8 0.0 0.0 1.0"/>
  </material>
  <material name="blue">
    <color rgba="0.0 0.0 0.8 1.0"/>
  </material>
  <material name="green">
    <color rgba="0.0 0.8 0.0 1.0"/>
  </material>
  <material name="grey">
    <color rgba="0.5 0.5 0.5 1.0"/>
  </material>
  <material name="orange">
    <color rgba="1.0 0.4235294117647059 0.0392156862745098 1.0"/>
  </material>
  <material name="brown">
    <color rgba="0.8705882352941177 0.8117647058823529 0.7647058823529411 1.0"/>
  </material>
  <joint name="camera_joint_depth" type="fixed">
    <parent link="base_link"/>
    <child link="camera_link_depth"/>
    <origin rpy="0 0 0" xyz="0.02 0 5.02"/>
  </joint>
  <link name="camera_link_depth">
    <visual>
      <geometry>
        <box size="0.010 0.03 0.03"/>
      </geometry>
      <material name="red"/>
    </visual>
  </link>
  <joint name="camera_optical_joint_depth" type="fixed">
    <parent link="camera_link_depth"/>
    <child link="camera_link_optical_depth"/>
    <origin rpy="-1.5707963267948966 0 -1.5707963267948966" xyz="0 0 5"/>
  </joint>
  <link name="camera_link_optical_depth"/>
  <gazebo reference="camera_link_depth">
    <material>Gazebo/Red</material>
    <sensor name="rgbd_camera" type="rgbd_camera">
      <pose> 0 0 0 0 0 0 </pose>
      <visualize>true</visualize>
      <update_rate>10</update_rate>
      <camera>
        <horizontal_fov>1.089</horizontal_fov>
        <image>
          <format>B8G8R8</format>
          <width>320</width>
          <height>240</height>
        </image>
        <clip>
          <near>0.3</near>
          <far>15</far>
        </clip>
      </camera>
      <always_on>1</always_on>
      <update_rate>20</update_rate>
      <visualize>true</visualize>
      <topic>depth_camera</topic>
      <gz_frame_id>camera_link_depth</gz_frame_id>
    </sensor>
  </gazebo>
  <!-- Specify some standard inertial calculations https://en.wikipedia.org/wiki/List_of_moments_of_inertia -->
  <!-- These make use of xacro's mathematical functionality -->
  <gazebo reference="sonar_frame">
    <sensor name="sonar" type="gpu_ray">
      <!-- <pose>1.54601 -0.004325 0.730815 0 0 0</pose> -->
      <pose>0 0 0 0 0 0</pose>
      <update_rate>5</update_rate>
      <topic>sonar</topic>
      <ray>
        <scan>
          <horizontal>
            <samples>100</samples>
            <resolution>1</resolution>
            <min_angle>-1.57</min_angle>
            <max_angle>1.57</max_angle>
          </horizontal>
          <vertical>
            <samples>20</samples>
            <resolution>1</resolution>
            <min_angle>-0.76</min_angle>
            <max_angle>1.57</max_angle>
          </vertical>
        </scan>
        <range>
          <min>0.10000000000000001</min>
          <max>130</max>
        </range>
        <noise>
          <type>gaussian</type>
          <mean>0</mean>
          <stddev>0.01</stddev>
        </noise>
      </ray>
    </sensor>
  </gazebo>
  <gazebo>
    <plugin filename="gz-sim-buoyancy-engine-system" name="gz::sim::systems::BuoyancyEngine">
      <link_name>base_link</link_name>
      <namespace>rov_ricketts</namespace>
      <min_volume>-30.0</min_volume>
      <neutral_volume>4.7</neutral_volume>
      <default_volume>-3.85</default_volume>
      <max_volume>30.0</max_volume>
      <surface>100.0</surface>
      <max_inflation_rate>2.5</max_inflation_rate>
    </plugin>
    <plugin filename="gz-sim-odometry-publisher-system" name="gz::sim::systems::OdometryPublisher">
      </plugin>
  </gazebo>
  <!-- This macro is used to define ROV body as UNIQUE LINK. 
       Useful if you want to set a simple approxiametd Inertia for the overall body -->
  <link name="base_link">
    <inertial>
      <origin rpy="0 0 0" xyz="0.0 0.0 -0.5"/>
      <mass value="4700.0"/>
      <inertia ixx="2538.0" ixy="0.0" ixz="0.0" iyy="5534.249999999999" iyz="0.0" izz="5534.249999999999"/>
    </inertial>
    <!-- float frame + side logo panel -->
    <visual>
      <origin rpy="0 0 0" xyz="1.8143 -0.004215 -0.560595"/>
      <geometry>
        <mesh filename="file:///home/harivathsha/rov-ricketts/install/rov_ricketts_description/share/rov_ricketts_description/meshes/floatLogo.dae" scale="1.0 1.0 1.0"/>
      </geometry>
    </visual>
    <!-- alluminium structure frame -->
    <visual>
      <origin rpy="0 0 0" xyz="1.8143 -0.004215 -0.560595"/>
      <geometry>
        <mesh filename="file:///home/harivathsha/rov-ricketts/install/rov_ricketts_description/share/rov_ricketts_description/meshes/frame.dae" scale="1.0 1.0 1.0"/>
      </geometry>
    </visual>
    <!-- all 7 thrusters' case frames -->
    <visual>
      <origin rpy="0 0 0" xyz="1.8143 -0.004215 -0.560595"/>
      <geometry>
        <mesh filename="file:///home/harivathsha/rov-ricketts/install/rov_ricketts_description/share/rov_ricketts_description/meshes/thrusters.dae" scale="1.0 1.0 1.0"/>
      </geometry>
    </visual>
    <!-- internal equipment frame -->
    <!-- <visual>
        <origin
          xyz="1.8143 -0.004215 -0.560595"
          rpy="0 0 0" />
        <geometry>
          <mesh
            filename="file://$(find rov_ricketts_description)/meshes/equipment.dae" scale="1.0 1.0 1.0"/>
        </geometry>
      </visual> -->
    <!-- simple box collision model -->
    <collision>
      <origin rpy="0 0 0" xyz="0 0 -0.3"/>
      <geometry>
        <box size="3.5 1.90 2.0"/>
      </geometry>
    </collision>
  </link>
  <!-- dummy link -->
  <joint name="base_link_frame" type="fixed">
    <origin rpy="0 0 0" xyz="1.8143 -0.004215 -0.560595"/>
    <parent link="base_link"/>
    <child link="base_frame"/>
  </joint>
  <link name="base_frame">
    </link>
  <joint name="base_sonar_frame" type="fixed">
    <origin rpy="0 0 0" xyz="1.54601 -0.004325 0.730815"/>
    <parent link="base_link"/>
    <child link="sonar_frame"/>
  </joint>
  <link name="sonar_frame">
    <!-- dummy inertial values for gazebo-->
    <inertial>
      <origin rpy="0 0 0" xyz="0 0 0"/>
      <mass value="0.00000001"/>
      <inertia ixx="1e-12" ixy="0" ixz="0" iyy="1e-12" iyz="0" izz="1e-12"/>
    </inertial>
  </link>
  <gazebo reference="base_link">
    <light name="rigth_up" type="spot">
      <pose>1.85 -0.628776 0.223158 0 -1.57 0</pose>
      <!-- Position the light slightly above base_link -->
      <attenuation>
        <range>25</range>
        <linear>0</linear>
        <constant>0.1</constant>
        <quadratic>0.005</quadratic>
      </attenuation>
      <diffuse>0.5 0.5 0.8 1</diffuse>
      <specular>0.8 0.8 0.5 1</specular>
      <spot>
        <inner_angle>1</inner_angle>
        <outer_angle>1.1</outer_angle>
        <falloff>1</falloff>
      </spot>
      <direction>0 0 -1</direction>
      <cast_shadows>true</cast_shadows>
      <visualize>false</visualize>
    </light>
  </gazebo>
  <gazebo reference="base_link">
    <light name="rigth_down" type="spot">
      <pose>1.87 -0.757185 -0.048437 0 -1.57 0</pose>
      <!-- Position the light slightly above base_link -->
      <attenuation>
        <range>25</range>
        <linear>0</linear>
        <constant>0.1</constant>
        <quadratic>0.005</quadratic>
      </attenuation>
      <diffuse>0.5 0.5 0.8 1</diffuse>
      <specular>0.8 0.8 0.5 1</specular>
      <spot>
        <inner_angle>1</inner_angle>
        <outer_angle>1.1</outer_angle>
        <falloff>1</falloff>
      </spot>
      <direction>0 0 -1</direction>
      <cast_shadows>true</cast_shadows>
      <visualize>false</visualize>
    </light>
  </gazebo>
  <gazebo reference="base_link">
    <light name="left_up" type="spot">
      <pose>1.87 0.62132 0.224733 0 -1.57 0</pose>
      <!-- Position the light slightly above base_link -->
      <attenuation>
        <range>25</range>
        <linear>0</linear>
        <constant>0.1</constant>
        <quadratic>0.005</quadratic>
      </attenuation>
      <diffuse>0.5 0.5 0.8 1</diffuse>
      <specular>0.8 0.8 0.5 1</specular>
      <spot>
        <inner_angle>1</inner_angle>
        <outer_angle>1.1</outer_angle>
        <falloff>1</falloff>
      </spot>
      <direction>0 0 -1</direction>
      <cast_shadows>true</cast_shadows>
      <visualize>false</visualize>
    </light>
  </gazebo>
  <gazebo reference="base_link">
    <light name="left_down" type="spot">
      <pose>1.95 0.750751 0.00541 0 -1.57 0</pose>
      <!-- Position the light slightly above base_link -->
      <attenuation>
        <range>25</range>
        <linear>0</linear>
        <constant>0.1</constant>
        <quadratic>0.005</quadratic>
      </attenuation>
      <diffuse>0.5 0.5 0.8 1</diffuse>
      <specular>0.8 0.8 0.5 1</specular>
      <spot>
        <inner_angle>1</inner_angle>
        <outer_angle>1.1</outer_angle>
        <falloff>1</falloff>
      </spot>
      <direction>0 0 -1</direction>
      <cast_shadows>true</cast_shadows>
      <visualize>false</visualize>
    </light>
  </gazebo>
  <joint name="front_left_thruster" type="revolute">
    <origin rpy="0.7853981633974483 1.5707963267948966 0" xyz="-0.547848 0.4574 0.120838"/>
    <parent link="base_frame"/>
    <child link="front_left"/>
    <axis xyz="0 0 1"/>
    <limit effort="1E6" lower="-1E12" upper="1E12" velocity="100"/>
  </joint>
  <link name="front_left">
    <inertial>
      <origin rpy="0 0 0" xyz="1.29123983e-04 -4.30643335e-05  6.65557479e-04"/>
      <mass value="2.8201033788020022"/>
      <inertia ixx="1.36253391E-02" ixy="-3.62214961E-07" ixz="-6.16491988E-07" iyy="1.36232618E-02" iyz="-9.76544753E-06" izz="2.52722006E-02"/>
    </inertial>
    <visual>
      <origin rpy="0 0 0" xyz="0 0 0"/>
      <geometry>
        <mesh filename="file:///home/harivathsha/rov-ricketts/install/rov_ricketts_description/share/rov_ricketts_description/meshes/propeller.stl"/>
      </geometry>
      <material name="">
        <color rgba="0.5 0.5 0.5 1"/>
      </material>
    </visual>
    <collision>
      <origin rpy="0 0 0" xyz="0 0 0"/>
      <geometry>
        <mesh filename="file:///home/harivathsha/rov-ricketts/install/rov_ricketts_description/share/rov_ricketts_description/meshes/propeller.stl"/>
      </geometry>
    </collision>
  </link>
  <gazebo>
    <plugin filename="gz-sim-thruster-system" name="gz::sim::systems::Thruster">
      <joint_name>front_left_thruster</joint_name>
      <namespace>rov_ricketts</namespace>
      <thrust_coefficient>0.05</thrust_coefficient>
      <fluid_density>1000</fluid_density>
      <propeller_diameter>0.38</propeller_diameter>
      <max_thrust_cmd>10000</max_thrust_cmd>
      <min_thrust_cmd>-10000</min_thrust_cmd>
    </plugin>
  </gazebo>
  <joint name="front_right_thruster" type="revolute">
    <origin rpy="-0.7853981633974483 1.5707963267948966 0" xyz="-0.547848 -0.4574 0.120838"/>
    <parent link="base_frame"/>
    <child link="front_right"/>
    <axis xyz="0 0 1"/>
    <limit effort="1E6" lower="-1E12" upper="1E12" velocity="100"/>
  </joint>
  <link name="front_right">
    <inertial>
      <origin rpy="0 0 0" xyz="1.29123983e-04 -4.30643335e-05  6.65557479e-04"/>
      <mass value="2.8201033788020022"/>
      <inertia ixx="1.36253391E-02" ixy="-3.62214961E-07" ixz="-6.16491988E-07" iyy="1.36232618E-02" iyz="-9.76544753E-06" izz="2.52722006E-02"/>
    </inertial>
    <visual>
      <origin rpy="0 0 0" xyz="0 0 0"/>
      <geometry>
        <mesh filename="file:///home/harivathsha/rov-ricketts/install/rov_ricketts_description/share/rov_ricketts_description/meshes/propeller.stl"/>
      </geometry>
      <material name="">
        <color rgba="0.5 0.5 0.5 1"/>
      </material>
    </visual>
    <collision>
      <origin rpy="0 0 0" xyz="0 0 0"/>
      <geometry>
        <mesh filename="file:///home/harivathsha/rov-ricketts/install/rov_ricketts_description/share/rov_ricketts_description/meshes/propeller.stl"/>
      </geometry>
    </collision>
  </link>
  <gazebo>
    <plugin filename="gz-sim-thruster-system" name="gz::sim::systems::Thruster">
      <joint_name>front_right_thruster</joint_name>
      <namespace>rov_ricketts</namespace>
      <thrust_coefficient>0.05</thrust_coefficient>
      <fluid_density>1000</fluid_density>
      <propeller_diameter>0.38</propeller_diameter>
      <max_thrust_cmd>10000</max_thrust_cmd>
      <min_thrust_cmd>-10000</min_thrust_cmd>
    </plugin>
  </gazebo>
  <joint name="rear_right_thruster" type="revolute">
    <origin rpy="-2.356194490192345 1.5707963267948966 0" xyz="-3.10256  -0.584898 0.121177"/>
    <parent link="base_frame"/>
    <child link="rear_right"/>
    <axis xyz="0 0 1"/>
    <limit effort="1E6" lower="-1E12" upper="1E12" velocity="100"/>
  </joint>
  <link name="rear_right">
    <inertial>
      <origin rpy="0 0 0" xyz="1.29123983e-04 -4.30643335e-05  6.65557479e-04"/>
      <mass value="2.8201033788020022"/>
      <inertia ixx="1.36253391E-02" ixy="-3.62214961E-07" ixz="-6.16491988E-07" iyy="1.36232618E-02" iyz="-9.76544753E-06" izz="2.52722006E-02"/>
    </inertial>
    <visual>
      <origin rpy="0 0 0" xyz="0 0 0"/>
      <geometry>
        <mesh filename="file:///home/harivathsha/rov-ricketts/install/rov_ricketts_description/share/rov_ricketts_description/meshes/propeller.stl"/>
      </geometry>
      <material name="">
        <color rgba="0.5 0.5 0.5 1"/>
      </material>
    </visual>
    <collision>
      <origin rpy="0 0 0" xyz="0 0 0"/>
      <geometry>
        <mesh filename="file:///home/harivathsha/rov-ricketts/install/rov_ricketts_description/share/rov_ricketts_description/meshes/propeller.stl"/>
      </geometry>
    </collision>
  </link>
  <gazebo>
    <plugin filename="gz-sim-thruster-system" name="gz::sim::systems::Thruster">
      <joint_name>rear_right_thruster</joint_name>
      <namespace>rov_ricketts</namespace>
      <thrust_coefficient>0.05</thrust_coefficient>
      <fluid_density>1000</fluid_density>
      <propeller_diameter>0.38</propeller_diameter>
      <max_thrust_cmd>10000</max_thrust_cmd>
      <min_thrust_cmd>-10000</min_thrust_cmd>
    </plugin>
  </gazebo>
  <joint name="rear_left_thruster" type="revolute">
    <origin rpy="2.356194490192345 1.5707963267948966 0" xyz="-3.10256   0.584898 0.121177"/>
    <parent link="base_frame"/>
    <child link="rear_left"/>
    <axis xyz="0 0 1"/>
    <limit effort="1E6" lower="-1E12" upper="1E12" velocity="100"/>
  </joint>
  <link name="rear_left">
    <inertial>
      <origin rpy="0 0 0" xyz="1.29123983e-04 -4.30643335e-05  6.65557479e-04"/>
      <mass value="2.8201033788020022"/>
      <inertia ixx="1.36253391E-02" ixy="-3.62214961E-07" ixz="-6.16491988E-07" iyy="1.36232618E-02" iyz="-9.76544753E-06" izz="2.52722006E-02"/>
    </inertial>
    <visual>
      <origin rpy="0 0 0" xyz="0 0 0"/>
      <geometry>
        <mesh filename="file:///home/harivathsha/rov-ricketts/install/rov_ricketts_description/share/rov_ricketts_description/meshes/propeller.stl"/>
      </geometry>
      <material name="">
        <color rgba="0.5 0.5 0.5 1"/>
      </material>
    </visual>
    <collision>
      <origin rpy="0 0 0" xyz="0 0 0"/>
      <geometry>
        <mesh filename="file:///home/harivathsha/rov-ricketts/install/rov_ricketts_description/share/rov_ricketts_description/meshes/propeller.stl"/>
      </geometry>
    </collision>
  </link>
  <gazebo>
    <plugin filename="gz-sim-thruster-system" name="gz::sim::systems::Thruster">
      <joint_name>rear_left_thruster</joint_name>
      <namespace>rov_ricketts</namespace>
      <thrust_coefficient>0.05</thrust_coefficient>
      <fluid_density>1000</fluid_density>
      <propeller_diameter>0.38</propeller_diameter>
      <max_thrust_cmd>10000</max_thrust_cmd>
      <min_thrust_cmd>-10000</min_thrust_cmd>
    </plugin>
  </gazebo>
  <joint name="up_rear_thruster" type="revolute">
    <origin rpy="0 0 0" xyz="-3.10346   -0.000003 0.787413"/>
    <parent link="base_frame"/>
    <child link="up_rear"/>
    <axis xyz="0 0 1"/>
    <limit effort="1E6" lower="-1E12" upper="1E12" velocity="100"/>
  </joint>
  <link name="up_rear">
    <inertial>
      <origin rpy="0 0 0" xyz="1.29123983e-04 -4.30643335e-05  6.65557479e-04"/>
      <mass value="2.8201033788020022"/>
      <inertia ixx="1.36253391E-02" ixy="-3.62214961E-07" ixz="-6.16491988E-07" iyy="1.36232618E-02" iyz="-9.76544753E-06" izz="2.52722006E-02"/>
    </inertial>
    <visual>
      <origin rpy="0 0 0" xyz="0 0 0"/>
      <geometry>
        <mesh filename="file:///home/harivathsha/rov-ricketts/install/rov_ricketts_description/share/rov_ricketts_description/meshes/propeller.stl"/>
      </geometry>
      <material name="">
        <color rgba="0.5 0.5 0.5 1"/>
      </material>
    </visual>
    <collision>
      <origin rpy="0 0 0" xyz="0 0 0"/>
      <geometry>
        <mesh filename="file:///home/harivathsha/rov-ricketts/install/rov_ricketts_description/share/rov_ricketts_description/meshes/propeller.stl"/>
      </geometry>
    </collision>
  </link>
  <gazebo>
    <plugin filename="gz-sim-thruster-system" name="gz::sim::systems::Thruster">
      <joint_name>up_rear_thruster</joint_name>
      <namespace>rov_ricketts</namespace>
      <thrust_coefficient>0.05</thrust_coefficient>
      <fluid_density>1000</fluid_density>
      <propeller_diameter>0.38</propeller_diameter>
      <max_thrust_cmd>10000</max_thrust_cmd>
      <min_thrust_cmd>-10000</min_thrust_cmd>
    </plugin>
  </gazebo>
  <joint name="up_front_left_thruster" type="revolute">
    <origin rpy="0.2617993877991494 0 0" xyz="-1.23346   0.652772  0.814842"/>
    <parent link="base_frame"/>
    <child link="up_front_left"/>
    <axis xyz="0 0 1"/>
    <limit effort="1E6" lower="-1E12" upper="1E12" velocity="100"/>
  </joint>
  <link name="up_front_left">
    <inertial>
      <origin rpy="0 0 0" xyz="1.29123983e-04 -4.30643335e-05  6.65557479e-04"/>
      <mass value="2.8201033788020022"/>
      <inertia ixx="1.36253391E-02" ixy="-3.62214961E-07" ixz="-6.16491988E-07" iyy="1.36232618E-02" iyz="-9.76544753E-06" izz="2.52722006E-02"/>
    </inertial>
    <visual>
      <origin rpy="0 0 0" xyz="0 0 0"/>
      <geometry>
        <mesh filename="file:///home/harivathsha/rov-ricketts/install/rov_ricketts_description/share/rov_ricketts_description/meshes/propeller.stl"/>
      </geometry>
      <material name="">
        <color rgba="0.5 0.5 0.5 1"/>
      </material>
    </visual>
    <collision>
      <origin rpy="0 0 0" xyz="0 0 0"/>
      <geometry>
        <mesh filename="file:///home/harivathsha/rov-ricketts/install/rov_ricketts_description/share/rov_ricketts_description/meshes/propeller.stl"/>
      </geometry>
    </collision>
  </link>
  <gazebo>
    <plugin filename="gz-sim-thruster-system" name="gz::sim::systems::Thruster">
      <joint_name>up_front_left_thruster</joint_name>
      <namespace>rov_ricketts</namespace>
      <thrust_coefficient>0.05</thrust_coefficient>
      <fluid_density>1000</fluid_density>
      <propeller_diameter>0.38</propeller_diameter>
      <max_thrust_cmd>10000</max_thrust_cmd>
      <min_thrust_cmd>-10000</min_thrust_cmd>
    </plugin>
  </gazebo>
  <joint name="up_front_right_thruster" type="revolute">
    <origin rpy="-0.2617993877991494 0 0" xyz="-1.23346   -0.652772 0.814842"/>
    <parent link="base_frame"/>
    <child link="up_front_right"/>
    <axis xyz="0 0 1"/>
    <limit effort="1E6" lower="-1E12" upper="1E12" velocity="100"/>
  </joint>
  <link name="up_front_right">
    <inertial>
      <origin rpy="0 0 0" xyz="1.29123983e-04 -4.30643335e-05  6.65557479e-04"/>
      <mass value="2.8201033788020022"/>
      <inertia ixx="1.36253391E-02" ixy="-3.62214961E-07" ixz="-6.16491988E-07" iyy="1.36232618E-02" iyz="-9.76544753E-06" izz="2.52722006E-02"/>
    </inertial>
    <visual>
      <origin rpy="0 0 0" xyz="0 0 0"/>
      <geometry>
        <mesh filename="file:///home/harivathsha/rov-ricketts/install/rov_ricketts_description/share/rov_ricketts_description/meshes/propeller.stl"/>
      </geometry>
      <material name="">
        <color rgba="0.5 0.5 0.5 1"/>
      </material>
    </visual>
    <collision>
      <origin rpy="0 0 0" xyz="0 0 0"/>
      <geometry>
        <mesh filename="file:///home/harivathsha/rov-ricketts/install/rov_ricketts_description/share/rov_ricketts_description/meshes/propeller.stl"/>
      </geometry>
    </collision>
  </link>
  <gazebo>
    <plugin filename="gz-sim-thruster-system" name="gz::sim::systems::Thruster">
      <joint_name>up_front_right_thruster</joint_name>
      <namespace>rov_ricketts</namespace>
      <thrust_coefficient>0.05</thrust_coefficient>
      <fluid_density>1000</fluid_density>
      <propeller_diameter>0.38</propeller_diameter>
      <max_thrust_cmd>10000</max_thrust_cmd>
      <min_thrust_cmd>-10000</min_thrust_cmd>
    </plugin>
  </gazebo>
  <ros2_control name="GazeboSystem" type="system">
    <hardware>
      <plugin>gz_ros2_control/GazeboSimSystem</plugin>
    </hardware>
    <joint name="arm_base_joint">
      <command_interface name="position">
        <param name="min">-2</param>
        <param name="max">2</param>
      </command_interface>
      <state_interface name="position">
        <param name="initial_value">0.0</param>
      </state_interface>
      <state_interface name="velocity"/>
      <state_interface name="effort"/>
    </joint>
    <joint name="arm_base_link1">
      <command_interface name="position">
        <param name="min">-2</param>
        <param name="max">2</param>
      </command_interface>
      <state_interface name="position">
        <param name="initial_value">0.0</param>
      </state_interface>
      <state_interface name="velocity"/>
      <state_interface name="effort"/>
    </joint>
    <joint name="arm_link1_link2">
      <command_interface name="position">
        <param name="min">-2</param>
        <param name="max">2</param>
      </command_interface>
      <state_interface name="position">
        <param name="initial_value">0.0</param>
      </state_interface>
      <state_interface name="velocity"/>
      <state_interface name="effort"/>
    </joint>
    <joint name="arm_link2_link3">
      <command_interface name="position">
        <param name="min">-2</param>
        <param name="max">2</param>
      </command_interface>
      <state_interface name="position">
        <param name="initial_value">0.0</param>
      </state_interface>
      <state_interface name="velocity"/>
      <state_interface name="effort"/>
    </joint>
    <joint name="arm_link3_link4">
      <command_interface name="position">
        <param name="min">-2</param>
        <param name="max">2</param>
      </command_interface>
      <state_interface name="position">
        <param name="initial_value">0.0</param>
      </state_interface>
      <state_interface name="velocity"/>
      <state_interface name="effort"/>
    </joint>
    <joint name="arm_link4_link5">
      <command_interface name="position">
        <param name="min">-2</param>
        <param name="max">2</param>
      </command_interface>
      <state_interface name="position">
        <param name="initial_value">0.0</param>
      </state_interface>
      <state_interface name="velocity"/>
      <state_interface name="effort"/>
    </joint>
    <joint name="arm_link5_claw_right">
      <command_interface name="position">
        <param name="min">-2</param>
        <param name="max">2</param>
      </command_interface>
      <state_interface name="position">
        <param name="initial_value">0.0</param>
      </state_interface>
      <state_interface name="velocity"/>
      <state_interface name="effort"/>
    </joint>
  </ros2_control>
  <gazebo>
    <plugin filename="libgz_ros2_control-system.so" name="gz_ros2_control::GazeboSimROS2ControlPlugin">
      <parameters>/home/harivathsha/rov-ricketts/install/rov_ricketts_description/share/rov_ricketts_description/config/my_controllers.yaml</parameters>
      <parameters>/home/harivathsha/rov-ricketts/install/rov_ricketts_description/share/rov_ricketts_description/config/gaz_ros2_ctl_use_sim.yaml</parameters>
    </plugin>
  </gazebo>
  <!-- Load joint state publisher gazebo plugin -->
  <!-- Gazebo plugin for joint state publisher  -->
  <gazebo>
    <plugin filename="gz-sim-joint-state-publisher-system" name="gz::sim::systems::JointStatePublisher">
      <!-- <update_rate>500</update_rate> -->
      <topic>/joint_states</topic>
      <!-- <joint_name>base_float_joint</joint_name> -->
      <joint_name>front_left_thruster</joint_name>
      <joint_name>front_right_thruster</joint_name>
      <joint_name>rear_right_thruster</joint_name>
      <joint_name>rear_left_thruster</joint_name>
      <joint_name>up_rear_thruster</joint_name>
      <joint_name>up_front_left_thruster</joint_name>
      <joint_name>up_front_right_thruster</joint_name>
    </plugin>
  </gazebo>
</robot>
